Workbook

Sheet Overall Analysis
A1: Department | B1: Email address | C1: First name | D1: Last name | E1: MCQ | F1: Debugging | G1: Coding | H1: Total | I1: Performance Category | J1: Completion Status
A2: AI&DS | B2: 2k24aids001@kiot.ac.in | C2: Aarthi S | E2: =LOOKUP(2,1/(MCQ!C:C=B2),MCQ!H:H) -> 25.00 | F2: =LOOKUP(2,1/(Debugging!C:C=B2),Debugging!H:H) -> 43.00 | G2: =LOOKUP(2,1/(Coding!C:C=B2),Coding!H:H) -> 20.50 | H2: =E2+F2+G2 -> 88.5 | I2: =IF(J2<>"Complete","Not Active",IF(H2>=75,"Good",IF(H2>=50,"Satisfactory",IF(H2>=25,"Need Attention","Intervention")))) -> Good | J2: =IF(COUNTIF(E2:G2,"#N/A")=3,"Not Attempted",IF(OR(ISNA(E2),ISNA(F2),ISNA(G2)),"NotCompleted","Complete")) -> Complete
A3: AI&DS | B3: 2k24aids002@kiot.ac.in | C3: Abhishek B | E3: =LOOKUP(2,1/(MCQ!C:C=B3),MCQ!H:H) -> 25.00 | F3: =LOOKUP(2,1/(Debugging!C:C=B3),Debugging!H:H) -> 37.00 | G3: =LOOKUP(2,1/(Coding!C:C=B3),Coding!H:H) -> 22.50 | H3: =E3+F3+G3 -> 84.5 | I3: =IF(J3<>"Complete","Not Active",IF(H3>=75,"Good",IF(H3>=50,"Satisfactory",IF(H3>=25,"Need Attention","Intervention")))) -> Good | J3: =IF(COUNTIF(E3:G3,"#N/A")=3,"Not Attempted",IF(OR(ISNA(E3),ISNA(F3),ISNA(G3)),"NotCompleted","Complete")) -> Complete
A4: AI&DS | B4: 2k24aids003@kiot.ac.in | C4: Abinesh S | E4: =LOOKUP(2,1/(MCQ!C:C=B4),MCQ!H:H) -> 24.00 | F4: =LOOKUP(2,1/(Debugging!C:C=B4),Debugging!H:H) -> 48.00 | G4: =LOOKUP(2,1/(Coding!C:C=B4),Coding!H:H) -> 22.00 | H4: =E4+F4+G4 -> 94 | I4: =IF(J4<>"Complete","Not Active",IF(H4>=75,"Good",IF(H4>=50,"Satisfactory",IF(H4>=25,"Need Attention","Intervention")))) -> Good | J4: =IF(COUNTIF(E4:G4,"#N/A")=3,"Not Attempted",IF(OR(ISNA(E4),ISNA(F4),ISNA(G4)),"NotCompleted","Complete")) -> Complete
A5: AI&DS | B5: 2k24aids004@kiot.ac.in | C5: Abishek D | E5: =LOOKUP(2,1/(MCQ!C:C=B5),MCQ!H:H) -> 20.00 | F5: =LOOKUP(2,1/(Debugging!C:C=B5),Debugging!H:H) -> 50.00 | G5: =LOOKUP(2,1/(Coding!C:C=B5),Coding!H:H) -> 25.00 | H5: =E5+F5+G5 -> 95 | I5: =IF(J5<>"Complete","Not Active",IF(H5>=75,"Good",IF(H5>=50,"Satisfactory",IF(H5>=25,"Need Attention","Intervention")))) -> Good | J5: =IF(COUNTIF(E5:G5,"#N/A")=3,"Not Attempted",IF(OR(ISNA(E5),ISNA(F5),ISNA(G5)),"NotCompleted","Complete")) -> Complete
A6: AI&DS | B6: 2k24aids005@kiot.ac.in | C6: Ajay Dev A S | E6: =LOOKUP(2,1/(MCQ!C:C=B6),MCQ!H:H) -> 23.00 | F6: =LOOKUP(2,1/(Debugging!C:C=B6),Debugging!H:H) -> 38.00 | G6: =LOOKUP(2,1/(Coding!C:C=B6),Coding!H:H) -> 23.50 | H6: =E6+F6+G6 -> 84.5 | I6: =IF(J6<>"Complete","Not Active",IF(H6>=75,"Good",IF(H6>=50,"Satisfactory",IF(H6>=25,"Need Attention","Intervention")))) -> Good | J6: =IF(COUNTIF(E6:G6,"#N/A")=3,"Not Attempted",IF(OR(ISNA(E6),ISNA(F6),ISNA(G6)),"NotCompleted","Complete")) -> Complete
A7: AI&DS | B7: 2k24aids006@kiot.ac.in | C7: Akishasri T | E7: =LOOKUP(2,1/(MCQ!C:C=B7),MCQ!H:H) -> 25.00 | F7: =LOOKUP(2,1/(Debugging!C:C=B7),Debugging!H:H) -> 50.00 | G7: =LOOKUP(2,1/(Coding!C:C=B7),Coding!H:H) -> 25.00 | H7: =E7+F7+G7 -> 100 | I7: =IF(J7<>"Complete","Not Active",IF(H7>=75,"Good",IF(H7>=50,"Satisfactory",IF(H7>=25,"Need Attention","Intervention")))) -> Good | J7: =IF(COUNTIF(E7:G7,"#N/A")=3,"Not Attempted",IF(OR(ISNA(E7),ISNA(F7),ISNA(G7)),"NotCompleted","Complete")) -> Complete
A8: AI&DS | B8: 2k24aids007@kiot.ac.in | C8: Archana P | E8: =LOOKUP(2,1/(MCQ!C:C=B8),MCQ!H:H) -> 22.00 | F8: =LOOKUP(2,1/(Debugging!C:C=B8),Debugging!H:H) -> 35.00 | G8: =LOOKUP(2,1/(Coding!C:C=B8),Coding!H:H) -> 25.00 | H8: =E8+F8+G8 -> 82 | I8: =IF(J8<>"Complete","Not Active",IF(H8>=75,"Good",IF(H8>=50,"Satisfactory",IF(H8>=25,"Need Attention","Intervention")))) -> Good | J8: =IF(COUNTIF(E8:G8,"#N/A")=3,"Not Attempted",IF(OR(ISNA(E8),ISNA(F8),ISNA(G8)),"NotCompleted","Complete")) -> Complete
A9: AI&DS | B9: 2k24aids008@kiot.ac.in | C9: Ashika V | E9: =LOOKUP(2,1/(MCQ!C:C=B9),MCQ!H:H) -> 22.00 | F9: =LOOKUP(2,1/(Debugging!C:C=B9),Debugging!H:H) -> 41.00 | G9: =LOOKUP(2,1/(Coding!C:C=B9),Coding!H:H) -> 23.50 | H9: =E9+F9+G9 -> 86.5 | I9: =IF(J9<>"Complete","Not Active",IF(H9>=75,"Good",IF(H9>=50,"Satisfactory",IF(H9>=25,"Need Attention","Intervention")))) -> Good | J9: =IF(COUNTIF(E9:G9,"#N/A")=3,"Not Attempted",IF(OR(ISNA(E9),ISNA(F9),ISNA(G9)),"NotCompleted","Complete")) -> Complete
A10: AI&DS | B10: 2k24aids009@kiot.ac.in | C10: Bakkiyalakshmi M | E10: =LOOKUP(2,1/(MCQ!C:C=B10),MCQ!H:H) -> 24.00 | F10: =LOOKUP(2,1/(Debugging!C:C=B10),Debugging!H:H) -> 48.00 | G10: =LOOKUP(2,1/(Coding!C:C=B10),Coding!H:H) -> 25.00 | H10: =E10+F10+G10 -> 97 | I10: =IF(J10<>"Complete","Not Active",IF(H10>=75,"Good",IF(H10>=50,"Satisfactory",IF(H10>=25,"Need Attention","Intervention")))) -> Good | J10: =IF(COUNTIF(E10:G10,"#N/A")=3,"Not Attempted",IF(OR(ISNA(E10),ISNA(F10),ISNA(G10)),"NotCompleted","Complete")) -> Complete
A11: AI&DS | B11: 2k24aids010@kiot.ac.in | C11: Balaji V | E11: =LOOKUP(2,1/(MCQ!C:C=B11),MCQ!H:H) -> 24.00 | F11: =LOOKUP(2,1/(Debugging!C:C=B11),Debugging!H:H) -> 40.00 | G11: =LOOKUP(2,1/(Coding!C:C=B11),Coding!H:H) -> 21.50 | H11: =E11+F11+G11 -> 85.5 | I11: =IF(J11<>"Complete","Not Active",IF(H11>=75,"Good",IF(H11>=50,"Satisfactory",IF(H11>=25,"Need Attention","Intervention")))) -> Good | J11: =IF(COUNTIF(E11:G11,"#N/A")=3,"Not Attempted",IF(OR(ISNA(E11),ISNA(F11),ISNA(G11)),"NotCompleted","Complete")) -> Complete
A12: AI&DS | B12: 2k24aids011@kiot.ac.in | C12: Bharath A | E12: =LOOKUP(2,1/(MCQ!C:C=B12),MCQ!H:H) -> 24.00 | F12: =LOOKUP(2,1/(Debugging!C:C=B12),Debugging!H:H) -> 45.00 | G12: =LOOKUP(2,1/(Coding!C:C=B12),Coding!H:H) -> 25.00 | H12: =E12+F12+G12 -> 94 | I12: =IF(J12<>"Complete","Not Active",IF(H12>=75,"Good",IF(H12>=50,"Satisfactory",IF(H12>=25,"Need Attention","Intervention")))) -> Good | J12: =IF(COUNTIF(E12:G12,"#N/A")=3,"Not Attempted",IF(OR(ISNA(E12),ISNA(F12),ISNA(G12)),"NotCompleted","Complete")) -> Complete
A13: AI&DS | B13: 2k24aids012@kiot.ac.in | C13: Bharathi V | E13: =LOOKUP(2,1/(MCQ!C:C=B13),MCQ!H:H) -> 25.00 | F13: =LOOKUP(2,1/(Debugging!C:C=B13),Debugging!H:H) -> 37.00 | G13: =LOOKUP(2,1/(Coding!C:C=B13),Coding!H:H) -> 25.00 | H13: =E13+F13+G13 -> 87 | I13: =IF(J13<>"Complete","Not Active",IF(H13>=75,"Good",IF(H13>=50,"Satisfactory",IF(H13>=25,"Need Attention","Intervention")))) -> Good | J13: =IF(COUNTIF(E13:G13,"#N/A")=3,"Not Attempted",IF(OR(ISNA(E13),ISNA(F13),ISNA(G13)),"NotCompleted","Complete")) -> Complete
... A130: AI&DS | B130: 2k24aids129@kiot.ac.in | C130: Yash V | E130: =LOOKUP(2,1/(MCQ!C:C=B130),MCQ!H:H) -> 24.00 | F130: =LOOKUP(2,1/(Debugging!C:C=B130),Debugging!H:H) -> 36.00 | G130: =LOOKUP(2,1/(Coding!C:C=B130),Coding!H:H) -> 25.00 | H130: =E130+F130+G130 -> 85 | I130: =IF(J130<>"Complete","Not Active",IF(H130>=75,"Good",IF(H130>=50,"Satisfactory",IF(H130>=25,"Need Attention","Intervention")))) -> Good | J130: =IF(COUNTIF(E130:G130,"#N/A")=3,"Not Attempted",IF(OR(ISNA(E130),ISNA(F130),ISNA(G130)),"NotCompleted","Complete")) -> Complete
A131: CIVIL | B131: 2k24ce01@kiot.ac.in | C131: Bharath Kumar J R | D131: S | E131: =LOOKUP(2,1/(MCQ!C:C=B131),MCQ!H:H) -> #N/A | F131: =LOOKUP(2,1/(Debugging!C:C=B131),Debugging!H:H) -> #N/A | G131: =LOOKUP(2,1/(Coding!C:C=B131),Coding!H:H) -> #N/A | H131: =E131+F131+G131 -> #N/A | I131: =IF(J131<>"Complete","Not Active",IF(H131>=75,"Good",IF(H131>=50,"Satisfactory",IF(H131>=25,"Need Attention","Intervention")))) -> Not Active | J131: =IF(COUNTIF(E131:G131,"#N/A")=3,"Not Attempted",IF(OR(ISNA(E131),ISNA(F131),ISNA(G131)),"NotCompleted","Complete")) -> Not Attempted
A132: CIVIL | B132: 2k24ce02@kiot.ac.in | C132: Darshan Raaj G T | D132: S | E132: =LOOKUP(2,1/(MCQ!C:C=B132),MCQ!H:H) -> #N/A | F132: =LOOKUP(2,1/(Debugging!C:C=B132),Debugging!H:H) -> #N/A | G132: =LOOKUP(2,1/(Coding!C:C=B132),Coding!H:H) -> #N/A | H132: =E132+F132+G132 -> #N/A | I132: =IF(J132<>"Complete","Not Active",IF(H132>=75,"Good",IF(H132>=50,"Satisfactory",IF(H132>=25,"Need Attention","Intervention")))) -> Not Active | J132: =IF(COUNTIF(E132:G132,"#N/A")=3,"Not Attempted",IF(OR(ISNA(E132),ISNA(F132),ISNA(G132)),"NotCompleted","Complete")) -> Not Attempted
A133: CIVIL | B133: 2k24ce03@kiot.ac.in | C133: Gokula Sri S | D133: R | E133: =LOOKUP(2,1/(MCQ!C:C=B133),MCQ!H:H) -> #N/A | F133: =LOOKUP(2,1/(Debugging!C:C=B133),Debugging!H:H) -> #N/A | G133: =LOOKUP(2,1/(Coding!C:C=B133),Coding!H:H) -> #N/A | H133: =E133+F133+G133 -> #N/A | I133: =IF(J133<>"Complete","Not Active",IF(H133>=75,"Good",IF(H133>=50,"Satisfactory",IF(H133>=25,"Need Attention","Intervention")))) -> Not Active | J133: =IF(COUNTIF(E133:G133,"#N/A")=3,"Not Attempted",IF(OR(ISNA(E133),ISNA(F133),ISNA(G133)),"NotCompleted","Complete")) -> Not Attempted
A134: CIVIL | B134: 2k24ce04@kiot.ac.in | C134: Guruvishnu R | D134: B | E134: =LOOKUP(2,1/(MCQ!C:C=B134),MCQ!H:H) -> 24.00 | F134: =LOOKUP(2,1/(Debugging!C:C=B134),Debugging!H:H) -> #N/A | G134: =LOOKUP(2,1/(Coding!C:C=B134),Coding!H:H) -> #N/A | H134: =E134+F134+G134 -> #N/A | I134: =IF(J134<>"Complete","Not Active",IF(H134>=75,"Good",IF(H134>=50,"Satisfactory",IF(H134>=25,"Need Attention","Intervention")))) -> Not Active | J134: =IF(COUNTIF(E134:G134,"#N/A")=3,"Not Attempted",IF(OR(ISNA(E134),ISNA(F134),ISNA(G134)),"NotCompleted","Complete")) -> NotCompleted
A135: CIVIL | B135: 2k24ce05@kiot.ac.in | C135: Jodhieswaran S C | D135: S | E135: =LOOKUP(2,1/(MCQ!C:C=B135),MCQ!H:H) -> 23.00 | F135: =LOOKUP(2,1/(Debugging!C:C=B135),Debugging!H:H) -> #N/A | G135: =LOOKUP(2,1/(Coding!C:C=B135),Coding!H:H) -> #N/A | H135: =E135+F135+G135 -> #N/A | I135: =IF(J135<>"Complete","Not Active",IF(H135>=75,"Good",IF(H135>=50,"Satisfactory",IF(H135>=25,"Need Attention","Intervention")))) -> Not Active | J135: =IF(COUNTIF(E135:G135,"#N/A")=3,"Not Attempted",IF(OR(ISNA(E135),ISNA(F135),ISNA(G135)),"NotCompleted","Complete")) -> NotCompleted
A136: CIVIL | B136: 2k24ce06@kiot.ac.in | C136: Kishor K K | D136: S | E136: =LOOKUP(2,1/(MCQ!C:C=B136),MCQ!H:H) -> 23.00 | F136: =LOOKUP(2,1/(Debugging!C:C=B136),Debugging!H:H) -> #N/A | G136: =LOOKUP(2,1/(Coding!C:C=B136),Coding!H:H) -> #N/A | H136: =E136+F136+G136 -> #N/A | I136: =IF(J136<>"Complete","Not Active",IF(H136>=75,"Good",IF(H136>=50,"Satisfactory",IF(H136>=25,"Need Attention","Intervention")))) -> Not Active | J136: =IF(COUNTIF(E136:G136,"#N/A")=3,"Not Attempted",IF(OR(ISNA(E136),ISNA(F136),ISNA(G136)),"NotCompleted","Complete")) -> NotCompleted
A137: CIVIL | B137: 2k24ce07@kiot.ac.in | C137: Kishore M | D137: S | E137: =LOOKUP(2,1/(MCQ!C:C=B137),MCQ!H:H) -> #N/A | F137: =LOOKUP(2,1/(Debugging!C:C=B137),Debugging!H:H) -> #N/A | G137: =LOOKUP(2,1/(Coding!C:C=B137),Coding!H:H) -> #N/A | H137: =E137+F137+G137 -> #N/A | I137: =IF(J137<>"Complete","Not Active",IF(H137>=75,"Good",IF(H137>=50,"Satisfactory",IF(H137>=25,"Need Attention","Intervention")))) -> Not Active | J137: =IF(COUNTIF(E137:G137,"#N/A")=3,"Not Attempted",IF(OR(ISNA(E137),ISNA(F137),ISNA(G137)),"NotCompleted","Complete")) -> Not Attempted
A138: CIVIL | B138: 2k24ce08@kiot.ac.in | C138: Kishore Rayan B | D138: P | E138: =LOOKUP(2,1/(MCQ!C:C=B138),MCQ!H:H) -> 13.00 | F138: =LOOKUP(2,1/(Debugging!C:C=B138),Debugging!H:H) -> #N/A | G138: =LOOKUP(2,1/(Coding!C:C=B138),Coding!H:H) -> #N/A | H138: =E138+F138+G138 -> #N/A | I138: =IF(J138<>"Complete","Not Active",IF(H138>=75,"Good",IF(H138>=50,"Satisfactory",IF(H138>=25,"Need Attention","Intervention")))) -> Not Active | J138: =IF(COUNTIF(E138:G138,"#N/A")=3,"Not Attempted",IF(OR(ISNA(E138),ISNA(F138),ISNA(G138)),"NotCompleted","Complete")) -> NotCompleted
A139: CIVIL | B139: 2k24ce09@kiot.ac.in | C139: Kowshik S T | D139: P | E139: =LOOKUP(2,1/(MCQ!C:C=B139),MCQ!H:H) -> #N/A | F139: =LOOKUP(2,1/(Debugging!C:C=B139),Debugging!H:H) -> #N/A | G139: =LOOKUP(2,1/(Coding!C:C=B139),Coding!H:H) -> #N/A | H139: =E139+F139+G139 -> #N/A | I139: =IF(J139<>"Complete","Not Active",IF(H139>=75,"Good",IF(H139>=50,"Satisfactory",IF(H139>=25,"Need Attention","Intervention")))) -> Not Active | J139: =IF(COUNTIF(E139:G139,"#N/A")=3,"Not Attempted",IF(OR(ISNA(E139),ISNA(F139),ISNA(G139)),"NotCompleted","Complete")) -> Not Attempted
A140: CIVIL | B140: 2k24ce10@kiot.ac.in | C140: Lakshana D R | D140: M | E140: =LOOKUP(2,1/(MCQ!C:C=B140),MCQ!H:H) -> #N/A | F140: =LOOKUP(2,1/(Debugging!C:C=B140),Debugging!H:H) -> #N/A | G140: =LOOKUP(2,1/(Coding!C:C=B140),Coding!H:H) -> #N/A | H140: =E140+F140+G140 -> #N/A | I140: =IF(J140<>"Complete","Not Active",IF(H140>=75,"Good",IF(H140>=50,"Satisfactory",IF(H140>=25,"Need Attention","Intervention")))) -> Not Active | J140: =IF(COUNTIF(E140:G140,"#N/A")=3,"Not Attempted",IF(OR(ISNA(E140),ISNA(F140),ISNA(G140)),"NotCompleted","Complete")) -> Not Attempted
A141: CIVIL | B141: 2k24ce11@kiot.ac.in | C141: Leonard Brandt M J | D141: P | E141: =LOOKUP(2,1/(MCQ!C:C=B141),MCQ!H:H) -> 23.00 | F141: =LOOKUP(2,1/(Debugging!C:C=B141),Debugging!H:H) -> #N/A | G141: =LOOKUP(2,1/(Coding!C:C=B141),Coding!H:H) -> #N/A | H141: =E141+F141+G141 -> #N/A | I141: =IF(J141<>"Complete","Not Active",IF(H141>=75,"Good",IF(H141>=50,"Satisfactory",IF(H141>=25,"Need Attention","Intervention")))) -> Not Active | J141: =IF(COUNTIF(E141:G141,"#N/A")=3,"Not Attempted",IF(OR(ISNA(E141),ISNA(F141),ISNA(G141)),"NotCompleted","Complete")) -> NotCompleted
A142: CIVIL | B142: 2k24ce12@kiot.ac.in | C142: Lingesh S | D142: M | E142: =LOOKUP(2,1/(MCQ!C:C=B142),MCQ!H:H) -> #N/A | F142: =LOOKUP(2,1/(Coding!B:B=A142),Coding!G:G) -> #N/A | G142: =LOOKUP(2,1/(Coding!C:C=B142),Coding!H:H) -> #N/A | H142: =E142+F142+G142 -> #N/A | I142: =IF(J142<>"Complete","Not Active",IF(H142>=75,"Good",IF(H142>=50,"Satisfactory",IF(H142>=25,"Need Attention","Intervention")))) -> Not Active | J142: =IF(COUNTIF(E142:G142,"#N/A")=3,"Not Attempted",IF(OR(ISNA(E142),ISNA(F142),ISNA(G142)),"NotCompleted","Complete")) -> Not Attempted
A143: CIVIL | B143: 2k24ce13@kiot.ac.in | C143: Lingeshwar S R | D143: M | E143: =LOOKUP(2,1/(MCQ!C:C=B143),MCQ!H:H) -> #N/A | F143: =LOOKUP(2,1/(Debugging!C:C=B143),Debugging!H:H) -> #N/A | G143: =LOOKUP(2,1/(Coding!C:C=B143),Coding!H:H) -> #N/A | H143: =E143+F143+G143 -> #N/A | I143: =IF(J143<>"Complete","Not Active",IF(H143>=75,"Good",IF(H143>=50,"Satisfactory",IF(H143>=25,"Need Attention","Intervention")))) -> Not Active | J143: =IF(COUNTIF(E143:G143,"#N/A")=3,"Not Attempted",IF(OR(ISNA(E143),ISNA(F143),ISNA(G143)),"NotCompleted","Complete")) -> Not Attempted
A144: CIVIL | B144: 2k24ce14@kiot.ac.in | C144: Mohamed Arsath M | D144: M | E144: =LOOKUP(2,1/(MCQ!C:C=B144),MCQ!H:H) -> 25.00 | F144: =LOOKUP(2,1/(Debugging!C:C=B144),Debugging!H:H) -> #N/A | G144: =LOOKUP(2,1/(Coding!C:C=B144),Coding!H:H) -> #N/A | H144: =E144+F144+G144 -> #N/A | I144: =IF(J144<>"Complete","Not Active",IF(H144>=75,"Good",IF(H144>=50,"Satisfactory",IF(H144>=25,"Need Attention","Intervention")))) -> Not Active | J144: =IF(COUNTIF(E144:G144,"#N/A")=3,"Not Attempted",IF(OR(ISNA(E144),ISNA(F144),ISNA(G144)),"NotCompleted","Complete")) -> NotCompleted
A145: CIVIL | B145: 2k24ce15@kiot.ac.in | C145: Mohammed Mathrab A | D145: G | E145: =LOOKUP(2,1/(MCQ!C:C=B145),MCQ!H:H) -> 2.00 | F145: =LOOKUP(2,1/(Debugging!C:C=B145),Debugging!H:H) -> #N/A | G145: =LOOKUP(2,1/(Coding!C:C=B145),Coding!H:H) -> #N/A | H145: =E145+F145+G145 -> #N/A | I145: =IF(J145<>"Complete","Not Active",IF(H145>=75,"Good",IF(H145>=50,"Satisfactory",IF(H145>=25,"Need Attention","Intervention")))) -> Not Active | J145: =IF(COUNTIF(E145:G145,"#N/A")=3,"Not Attempted",IF(OR(ISNA(E145),ISNA(F145),ISNA(G145)),"NotCompleted","Complete")) -> NotCompleted
A146: CIVIL | B146: 2k24ce16@kiot.ac.in | C146: Mugilan M | D146: S | E146: =LOOKUP(2,1/(MCQ!C:C=B146),MCQ!H:H) -> 24.00 | F146: =LOOKUP(2,1/(Debugging!C:C=B146),Debugging!H:H) -> #N/A | G146: #N/A | H146: =E146+F146+G146 -> #N/A | I146: =IF(J146<>"Complete","Not Active",IF(H146>=75,"Good",IF(H146>=50,"Satisfactory",IF(H146>=25,"Need Attention","Intervention")))) -> Not Active | J146: =IF(COUNTIF(E146:G146,"#N/A")=3,"Not Attempted",IF(OR(ISNA(E146),ISNA(F146),ISNA(G146)),"NotCompleted","Complete")) -> NotCompleted
A147: CIVIL | B147: 2k24ce17@kiot.ac.in | C147: Muneeshwar R L | D147: M | E147: =LOOKUP(2,1/(MCQ!C:C=B147),MCQ!H:H) -> #N/A | F147: =LOOKUP(2,1/(Debugging!C:C=B147),Debugging!H:H) -> #N/A | G147: =LOOKUP(2,1/(Coding!C:C=B147),Coding!H:H) -> #N/A | H147: =E147+F147+G147 -> #N/A | I147: =IF(J147<>"Complete","Not Active",IF(H147>=75,"Good",IF(H147>=50,"Satisfactory",IF(H147>=25,"Need Attention","Intervention")))) -> Not Active | J147: =IF(COUNTIF(E147:G147,"#N/A")=3,"Not Attempted",IF(OR(ISNA(E147),ISNA(F147),ISNA(G147)),"NotCompleted","Complete")) -> Not Attempted
A148: CIVIL | B148: 2k24ce18@kiot.ac.in | C148: Nirmala R | D148: S | E148: =LOOKUP(2,1/(MCQ!C:C=B148),MCQ!H:H) -> #N/A | F148: =LOOKUP(2,1/(Debugging!C:C=B148),Debugging!H:H) -> #N/A | G148: =LOOKUP(2,1/(Coding!C:C=B148),Coding!H:H) -> #N/A | H148: =E148+F148+G148 -> #N/A | I148: =IF(J148<>"Complete","Not Active",IF(H148>=75,"Good",IF(H148>=50,"Satisfactory",IF(H148>=25,"Need Attention","Intervention")))) -> Not Active | J148: =IF(COUNTIF(E148:G148,"#N/A")=3,"Not Attempted",IF(OR(ISNA(E148),ISNA(F148),ISNA(G148)),"NotCompleted","Complete")) -> Not Attempted
A149: CIVIL | B149: 2k24ce19@kiot.ac.in | C149: Oviya B | D149: A | E149: =LOOKUP(2,1/(MCQ!C:C=B149),MCQ!H:H) -> 22.00 | F149: =LOOKUP(2,1/(Debugging!C:C=B149),Debugging!H:H) -> #N/A | G149: =LOOKUP(2,1/(Coding!C:C=B149),Coding!H:H) -> 23.50 | H149: =E149+F149+G149 -> #N/A | I149: =IF(J149<>"Complete","Not Active",IF(H149>=75,"Good",IF(H149>=50,"Satisfactory",IF(H149>=25,"Need Attention","Intervention")))) -> Not Active | J149: =IF(COUNTIF(E149:G149,"#N/A")=3,"Not Attempted",IF(OR(ISNA(E149),ISNA(F149),ISNA(G149)),"NotCompleted","Complete")) -> NotCompleted
A150: CIVIL | B150: 2k24ce20@kiot.ac.in | C150: Pradeep P | D150: G | E150: =LOOKUP(2,1/(MCQ!C:C=B150),MCQ!H:H) -> 22.00 | F150: =LOOKUP(2,1/(Debugging!C:C=B150),Debugging!H:H) -> #N/A | G150: =LOOKUP(2,1/(Coding!C:C=B150),Coding!H:H) -> #N/A | H150: =E150+F150+G150 -> #N/A | I150: =IF(J150<>"Complete","Not Active",IF(H150>=75,"Good",IF(H150>=50,"Satisfactory",IF(H150>=25,"Need Attention","Intervention")))) -> Not Active | J150: =IF(COUNTIF(E150:G150,"#N/A")=3,"Not Attempted",IF(OR(ISNA(E150),ISNA(F150),ISNA(G150)),"NotCompleted","Complete")) -> NotCompleted
A151: CIVIL | B151: 2k24ce21@kiot.ac.in | C151: Priyadharshini K | D151: E | E151: =LOOKUP(2,1/(MCQ!C:C=B151),MCQ!H:H) -> #N/A | F151: =LOOKUP(2,1/(Debugging!C:C=B151),Debugging!H:H) -> #N/A | G151: =LOOKUP(2,1/(Coding!C:C=B151),Coding!H:H) -> #N/A | H151: =E151+F151+G151 -> #N/A | I151: =IF(J151<>"Complete","Not Active",IF(H151>=75,"Good",IF(H151>=50,"Satisfactory",IF(H151>=25,"Need Attention","Intervention")))) -> Not Active | J151: =IF(COUNTIF(E151:G151,"#N/A")=3,"Not Attempted",IF(OR(ISNA(E151),ISNA(F151),ISNA(G151)),"NotCompleted","Complete")) -> Not Attempted
A152: CIVIL | B152: 2k24ce22@kiot.ac.in | C152: Ranjith S | D152: SA | E152: =LOOKUP(2,1/(MCQ!C:C=B152),MCQ!H:H) -> #N/A | F152: =LOOKUP(2,1/(Debugging!C:C=B152),Debugging!H:H) -> #N/A | G152: =LOOKUP(2,1/(Coding!C:C=B152),Coding!H:H) -> #N/A | H152: =E152+F152+G152 -> #N/A | I152: =IF(J152<>"Complete","Not Active",IF(H152>=75,"Good",IF(H152>=50,"Satisfactory",IF(H152>=25,"Need Attention","Intervention")))) -> Not Active | J152: =IF(COUNTIF(E152:G152,"#N/A")=3,"Not Attempted",IF(OR(ISNA(E152),ISNA(F152),ISNA(G152)),"NotCompleted","Complete")) -> Not Attempted
A153: CIVIL | B153: 2k24ce23@kiot.ac.in | C153: Risikaesh V S | D153: R | E153: =LOOKUP(2,1/(MCQ!C:C=B153),MCQ!H:H) -> 19.00 | F153: =LOOKUP(2,1/(Debugging!C:C=B153),Debugging!H:H) -> #N/A | G153: =LOOKUP(2,1/(Coding!C:C=B153),Coding!H:H) -> 15.00 | H153: =E153+F153+G153 -> #N/A | I153: =IF(J153<>"Complete","Not Active",IF(H153>=75,"Good",IF(H153>=50,"Satisfactory",IF(H153>=25,"Need Attention","Intervention")))) -> Not Active | J153: =IF(COUNTIF(E153:G153,"#N/A")=3,"Not Attempted",IF(OR(ISNA(E153),ISNA(F153),ISNA(G153)),"NotCompleted","Complete")) -> NotCompleted
A154: CIVIL | B154: 2k24ce24@kiot.ac.in | C154: Salman Khan S | D154: S | E154: =LOOKUP(2,1/(MCQ!C:C=B154),MCQ!H:H) -> #N/A | F154: =LOOKUP(2,1/(Debugging!C:C=B154),Debugging!H:H) -> #N/A | G154: =LOOKUP(2,1/(Coding!C:C=B154),Coding!H:H) -> #N/A | H154: =E154+F154+G154 -> #N/A | I154: =IF(J154<>"Complete","Not Active",IF(H154>=75,"Good",IF(H154>=50,"Satisfactory",IF(H154>=25,"Need Attention","Intervention")))) -> Not Active | J154: =IF(COUNTIF(E154:G154,"#N/A")=3,"Not Attempted",IF(OR(ISNA(E154),ISNA(F154),ISNA(G154)),"NotCompleted","Complete")) -> Not Attempted
A155: CIVIL | B155: 2k24ce25@kiot.ac.in | C155: Sanjay M | D155: A | E155: =LOOKUP(2,1/(MCQ!C:C=B155),MCQ!H:H) -> 24.00 | F155: =LOOKUP(2,1/(Debugging!C:C=B155),Debugging!H:H) -> #N/A | G155: =LOOKUP(2,1/(Coding!C:C=B155),Coding!H:H) -> #N/A | H155: =E155+F155+G155 -> #N/A | I155: =IF(J155<>"Complete","Not Active",IF(H155>=75,"Good",IF(H155>=50,"Satisfactory",IF(H155>=25,"Need Attention","Intervention")))) -> Not Active | J155: =IF(COUNTIF(E155:G155,"#N/A")=3,"Not Attempted",IF(OR(ISNA(E155),ISNA(F155),ISNA(G155)),"NotCompleted","Complete")) -> NotCompleted
A156: CIVIL | B156: 2k24ce26@kiot.ac.in | C156: Sathya S | D156: J | E156: =LOOKUP(2,1/(MCQ!C:C=B156),MCQ!H:H) -> #N/A | F156: =LOOKUP(2,1/(Debugging!C:C=B156),Debugging!H:H) -> #N/A | G156: =LOOKUP(2,1/(Coding!C:C=B156),Coding!H:H) -> #N/A | H156: =E156+F156+G156 -> #N/A | I156: =IF(J156<>"Complete","Not Active",IF(H156>=75,"Good",IF(H156>=50,"Satisfactory",IF(H156>=25,"Need Attention","Intervention")))) -> Not Active | J156: =IF(COUNTIF(E156:G156,"#N/A")=3,"Not Attempted",IF(OR(ISNA(E156),ISNA(F156),ISNA(G156)),"NotCompleted","Complete")) -> Not Attempted
...

Sheet MCQ
A1: Last name | B1: First name | C1: Email address | D1: Status | E1: Started | F1: Completed | G1: Duration | H1: Grade/25.00 | I1: Q. 1 /1.00 | J1: Q. 2 /1.00 | K1: Q. 3 /1.00 | L1: Q. 4 /1.00 | M1: Q. 5 /1.00 | N1: Q. 6 /1.00 | O1: Q. 7 /1.00 | P1: Q. 8 /1.00 | Q1: Q. 9 /1.00 | R1: Q. 10 /1.00 | S1: Q. 11 /1.00 | T1: Q. 12 /1.00 | U1: Q. 13 /1.00 | V1: Q. 14 /1.00 | W1: Q. 15 /1.00 | X1: Q. 16 /1.00 | Y1: Q. 17 /1.00 | Z1: Q. 18 /1.00 | AA1: Q. 19 /1.00 | AB1: Q. 20 /1.00 | AC1: Q. 21 /1.00 | AD1: Q. 22 /1.00 | AE1: Q. 23 /1.00 | AF1: Q. 24 /1.00 | AG1: Q. 25 /1.00
A2: K | B2: AADHIISHVAR | C2: 2k24ece001@kiot.ac.in | D2: Finished | E2: 18 August 2026 11:48 AM | F2: 18 August 2026 12:04 PM | G2: 15 mins 36 secs | H2: 19.00 | I2: 1.00 | J2: 0.00 | K2: 1.00 | L2: 0.00 | M2: 1.00 | N2: 0.00 | O2: 0.00 | P2: 1.00 | Q2: 1.00 | R2: 1.00 | S2: 1.00 | T2: 1.00 | U2: 1.00 | V2: 1.00 | W2: 0.00 | X2: 1.00 | Y2: 1.00 | Z2: 1.00 | AA2: 1.00 | AB2: 1.00 | AC2: 1.00 | AD2: 0.00 | AE2: 1.00 | AF2: 1.00 | AG2: 1.00
A3: S | B3: Aakash | C3: 2k24cse003@kiot.ac.in | D3: Finished | E3: 11 August 2026 8:30 PM | F3: 11 August 2026 8:46 PM | G3: 15 mins 28 secs | H3: 22.00 | I3: 1.00 | J3: 1.00 | K3: 1.00 | L3: 1.00 | M3: 1.00 | N3: 1.00 | O3: 0.00 | P3: 1.00 | Q3: 1.00 | R3: 1.00 | S3: 1.00 | T3: 1.00 | U3: 1.00 | V3: 1.00 | W3: 1.00 | X3: 0.00 | Y3: 1.00 | Z3: 1.00 | AA3: 1.00 | AB3: 1.00 | AC3: 1.00 | AD3: 1.00 | AE3: 0.00 | AF3: 1.00 | AG3: 1.00
A4: S | B4: AARTHI | C4: 2k24aids001@kiot.ac.in | D4: Finished | E4: 12 August 2026 1:42 PM | F4: 12 August 2026 2:07 PM | G4: 25 mins 10 secs | H4: 17.00 | I4: 1.00 | J4: 0.00 | K4: 1.00 | L4: 1.00 | M4: 1.00 | N4: 1.00 | O4: 0.00 | P4: 0.00 | Q4: 1.00 | R4: 1.00 | S4: 1.00 | T4: 0.00 | U4: 1.00 | V4: 1.00 | W4: 0.00 | X4: 1.00 | Y4: 1.00 | Z4: 0.00 | AA4: 1.00 | AB4: 0.00 | AC4: 1.00 | AD4: 1.00 | AE4: 0.00 | AF4: 1.00 | AG4: 1.00
A5: S | B5: AARTHI | C5: 2k24aids001@kiot.ac.in | D5: Finished | E5: 12 August 2026 2:47 PM | F5: 12 August 2026 2:52 PM | G5: 5 mins 48 secs | H5: 25.00 | I5: 1.00 | J5: 1.00 | K5: 1.00 | L5: 1.00 | M5: 1.00 | N5: 1.00 | O5: 1.00 | P5: 1.00 | Q5: 1.00 | R5: 1.00 | S5: 1.00 | T5: 1.00 | U5: 1.00 | V5: 1.00 | W5: 1.00 | X5: 1.00 | Y5: 1.00 | Z5: 1.00 | AA5: 1.00 | AB5: 1.00 | AC5: 1.00 | AD5: 1.00 | AE5: 1.00 | AF5: 1.00 | AG5: 1.00
A6: A | B6: Aarthi | C6: 2k24it001@kiot.ac.in | D6: Finished | E6: 18 August 2026 9:45 PM | F6: 18 August 2026 10:01 PM | G6: 15 mins 33 secs | H6: 22.00 | I6: 1.00 | J6: 1.00 | K6: 1.00 | L6: 1.00 | M6: 1.00 | N6: 1.00 | O6: 0.00 | P6: 0.00 | Q6: 1.00 | R6: 1.00 | S6: 1.00 | T6: 1.00 | U6: 1.00 | V6: 1.00 | W6: 1.00 | X6: 1.00 | Y6: 1.00 | Z6: 1.00 | AA6: 0.00 | AB6: 1.00 | AC6: 1.00 | AD6: 1.00 | AE6: 1.00 | AF6: 1.00 | AG6: 1.00
A7: A J | B7: Abarna | C7: 2k24cse004@kiot.ac.in | D7: Finished | E7: 18 August 2026 6:37 AM | F7: 18 August 2026 6:46 AM | G7: 9 mins 12 secs | H7: 19.00 | I7: 1.00 | J7: 1.00 | K7: 1.00 | L7: 1.00 | M7: 1.00 | N7: 1.00 | O7: 0.00 | P7: 1.00 | Q7: 1.00 | R7: 1.00 | S7: 0.00 | T7: 1.00 | U7: 1.00 | V7: 1.00 | W7: 1.00 | X7: 1.00 | Y7: 1.00 | Z7: 1.00 | AA7: - | AB7: 1.00 | AC7: 1.00 | AD7: 0.00 | AE7: 1.00 | AF7: 0.00 | AG7: 0.00
A8: A | B8: ABDUL RAHMAN | C8: 2k24ece002@kiot.ac.in | D8: Finished | E8: 12 August 2026 6:06 PM | F8: 12 August 2026 6:19 PM | G8: 12 mins 57 secs | H8: 24.00 | I8: 1.00 | J8: 1.00 | K8: 1.00 | L8: 1.00 | M8: 1.00 | N8: 1.00 | O8: 0.00 | P8: 1.00 | Q8: 1.00 | R8: 1.00 | S8: 1.00 | T8: 1.00 | U8: 1.00 | V8: 1.00 | W8: 1.00 | X8: 1.00 | Y8: 1.00 | Z8: 1.00 | AA8: 1.00 | AB8: 1.00 | AC8: 1.00 | AD8: 1.00 | AE8: 1.00 | AF8: 1.00 | AG8: 1.00
A9: M | B9: ABHEJEITH | C9: 2k24ece003@kiot.ac.in | D9: Finished | E9: 17 August 2026 1:49 PM | F9: 17 August 2026 2:02 PM | G9: 13 mins 23 secs | H9: 24.00 | I9: 1.00 | J9: 1.00 | K9: 1.00 | L9: 1.00 | M9: 1.00 | N9: 0.00 | O9: 1.00 | P9: 1.00 | Q9: 1.00 | R9: 1.00 | S9: 1.00 | T9: 1.00 | U9: 1.00 | V9: 1.00 | W9: 1.00 | X9: 1.00 | Y9: 1.00 | Z9: 1.00 | AA9: 1.00 | AB9: 1.00 | AC9: 1.00 | AD9: 1.00 | AE9: 1.00 | AF9: 1.00 | AG9: 1.00
A10: S | B10: ABHISHEEK | C10: 2k24ece004@kiot.ac.in | D10: Finished | E10: 15 August 2026 6:46 PM | F10: 15 August 2026 7:27 PM | G10: 40 mins 39 secs | H10: 21.00 | I10: 1.00 | J10: 1.00 | K10: 1.00 | L10: 1.00 | M10: 1.00 | N10: 1.00 | O10: 1.00 | P10: 0.00 | Q10: 1.00 | R10: 1.00 | S10: 1.00 | T10: 1.00 | U10: 1.00 | V10: 1.00 | W10: 1.00 | X10: 1.00 | Y10: 1.00 | Z10: 0.00 | AA10: - | AB10: 1.00 | AC10: 1.00 | AD10: 1.00 | AE10: 1.00 | AF10: 0.00 | AG10: 1.00
A11: B | B11: ABHISHEK | C11: 2k24aids002@kiot.ac.in | D11: Finished | E11: 12 August 2026 8:13 PM | F11: 12 August 2026 8:22 PM | G11: 9 mins 4 secs | H11: 25.00 | I11: 1.00 | J11: 1.00 | K11: 1.00 | L11: 1.00 | M11: 1.00 | N11: 1.00 | O11: 1.00 | P11: 1.00 | Q11: 1.00 | R11: 1.00 | S11: 1.00 | T11: 1.00 | U11: 1.00 | V11: 1.00 | W11: 1.00 | X11: 1.00 | Y11: 1.00 | Z11: 1.00 | AA11: 1.00 | AB11: 1.00 | AC11: 1.00 | AD11: 1.00 | AE11: 1.00 | AF11: 1.00 | AG11: 1.00
A12: N | B12: Abinaiyaa | C12: 2k24cse005@kiot.ac.in | D12: Finished | E12: 10 August 2026 8:34 PM | F12: 10 August 2026 9:19 PM | G12: 44 mins 38 secs | H12: 24.00 | I12: 1.00 | J12: 1.00 | K12: 1.00 | L12: 1.00 | M12: 1.00 | N12: 1.00 | O12: 0.00 | P12: 1.00 | Q12: 1.00 | R12: 1.00 | S12: 1.00 | T12: 1.00 | U12: 1.00 | V12: 1.00 | W12: 1.00 | X12: 1.00 | Y12: 1.00 | Z12: 1.00 | AA12: 1.00 | AB12: 1.00 | AC12: 1.00 | AD12: 1.00 | AE12: 1.00 | AF12: 1.00 | AG12: 1.00
... A860: S | B860: Yuvasri | C860: 2k24it120@kiot.ac.in | D860: Finished | E860: 13 August 2026 3:13 PM | F860: 13 August 2026 3:26 PM | G860: 12 mins 26 secs | H860: 24.00 | I860: 1.00 | J860: 1.00 | K860: 1.00 | L860: 1.00 | M860: 1.00 | N860: 1.00 | O860: 1.00 | P860: 1.00 | Q860: 0.00 | R860: 1.00 | S860: 1.00 | T860: 1.00 | U860: 1.00 | V860: 1.00 | W860: 1.00 | X860: 1.00 | Y860: 1.00 | Z860: 1.00 | AA860: 1.00 | AB860: 1.00 | AC860: 1.00 | AD860: 1.00 | AE860: 1.00 | AF860: 1.00 | AG860: 1.00
A861: Overall average | H861: 21.79 | I861: 0.97 | J861: 0.86 | K861: 0.96 | L861: 0.96 | M861: 0.98 | N861: 0.82 | O861: 0.80 | P861: 0.79 | Q861: 0.95 | R861: 0.92 | S861: 0.75 | T861: 0.87 | U861: 0.90 | V861: 0.92 | W861: 0.87 | X861: 0.78 | Y861: 0.91 | Z861: 0.90 | AA861: 0.86 | AB861: 0.88 | AC861: 0.78 | AD861: 0.75 | AE861: 0.81 | AF861: 0.89 | AG861: 0.89

Sheet Debugging
A1: Last name | B1: First name | C1: Email address | D1: Status | E1: Started | F1: Completed | G1: Duration | H1: Grade/50.00 | I1: Q. 1 /10.00 | J1: Q. 2 /10.00 | K1: Q. 3 /10.00 | L1: Q. 4 /10.00 | M1: Q. 5 /10.00
A2: S | B2: AARTHI | C2: 2k24aids001@kiot.ac.in | D2: Finished | E2: 12 August 2026 2:11 PM | F2: 12 August 2026 2:43 PM | G2: 31 mins 52 secs | H2: 43.00 | I2: 4.00 | J2: 9.00 | K2: 10.00 | L2: 10.00 | M2: 10.00
A3: B | B3: ABHISHEK | C3: 2k24aids002@kiot.ac.in | D3: Finished | E3: 12 August 2026 8:28 PM | F3: 12 August 2026 8:39 PM | G3: 11 mins 33 secs | H3: 0.00 | I3: 0.00 | J3: 0.00 | K3: 0.00 | L3: 0.00 | M3: 0.00
A4: B | B4: ABHISHEK | C4: 2k24aids002@kiot.ac.in | D4: Finished | E4: 15 August 2026 2:55 PM | F4: 15 August 2026 3:15 PM | G4: 20 mins 3 secs | H4: 37.00 | I4: 10.00 | J4: 9.00 | K4: 0.00 | L4: 9.00 | M4: 9.00
A5: S | B5: ABINESH | C5: 2k24aids003@kiot.ac.in | D5: Finished | E5: 15 August 2026 1:42 PM | F5: 15 August 2026 2:10 PM | G5: 27 mins 16 secs | H5: 39.00 | I5: 8.00 | J5: 5.00 | K5: 9.00 | L5: 8.00 | M5: 9.00
A6: S | B6: ABINESH | C6: 2k24aids003@kiot.ac.in | D6: Finished | E6: 15 August 2026 2:11 PM | F6: 15 August 2026 2:22 PM | G6: 11 mins 1 sec | H6: 48.00 | I6: 9.00 | J6: 9.00 | K6: 10.00 | L6: 10.00 | M6: 10.00
A7: D | B7: ABISHEK | C7: 2k24aids004@kiot.ac.in | D7: Finished | E7: 18 August 2026 9:31 AM | F7: 18 August 2026 9:37 AM | G7: 5 mins 21 secs | H7: 50.00 | I7: 10.00 | J7: 10.00 | K7: 10.00 | L7: 10.00 | M7: 10.00
A8: A S | B8: AJAY DEV | C8: 2k24aids005@kiot.ac.in | D8: Finished | E8: 12 August 2026 7:45 PM | F8: 12 August 2026 8:08 PM | G8: 22 mins 57 secs | H8: 38.00 | I8: 0.00 | J8: 10.00 | K8: 8.00 | L8: 10.00 | M8: 10.00
A9: T | B9: AKISHASRI | C9: 2k24aids006@kiot.ac.in | D9: Finished | E9: 12 August 2026 2:09 PM | F9: 12 August 2026 2:47 PM | G9: 38 mins 14 secs | H9: 33.00 | I9: 3.00 | J9: 8.00 | K9: 6.00 | L9: 7.00 | M9: 9.00
A10: T | B10: AKISHASRI | C10: 2k24aids006@kiot.ac.in | D10: Finished | E10: 12 August 2026 2:49 PM | F10: 12 August 2026 2:58 PM | G10: 8 mins 53 secs | H10: 50.00 | I10: 10.00 | J10: 10.00 | K10: 10.00 | L10: 10.00 | M10: 10.00
A11: P | B11: ARCHANA | C11: 2k24aids007@kiot.ac.in | D11: Finished | E11: 12 August 2026 2:14 PM | F11: 12 August 2026 2:52 PM | G11: 38 mins 4 secs | H11: 35.00 | I11: 3.00 | J11: 7.00 | K11: 8.00 | L11: 10.00 | M11: 7.00
A12: V | B12: ASHIKA | C12: 2k24aids008@kiot.ac.in | D12: Finished | E12: 12 August 2026 2:15 PM | F12: 12 August 2026 2:47 PM | G12: 32 mins 27 secs | H12: 41.00 | I12: 3.00 | J12: 9.00 | K12: 10.00 | L12: 9.00 | M12: 10.00
... A748: A | B748: Jagan | C748: 2k24me115@kiot.ac.in | D748: Finished | E748: 12 August 2026 7:17 PM | F748: 12 August 2026 7:49 PM | G748: 32 mins 10 secs | H748: 38.00 | I748: 9.00 | J748: 0.00 | K748: 10.00 | L748: 10.00 | M748: 9.00
A749: Overall average | H749: 37.37 | I749: 6.96 | J749: 7.55 | K749: 7.62 | L749: 7.71 | M749: 7.54

Sheet Coding
A1: Last name | B1: First name | C1: Email address | D1: Status | E1: Started | F1: Completed | G1: Duration | H1: Grade/25.00 | I1: Q. 1 /15.00 | J1: Q. 2 /10.00
A2: S | B2: AARTHI | C2: 2k24aids001@kiot.ac.in | D2: Finished | E2: 12 August 2026 2:53 PM | F2: 12 August 2026 3:03 PM | G2: 9 mins 56 secs | H2: 20.50 | I2: 10.50 | J2: 10.00
A3: B | B3: ABHISHEK | C3: 2k24aids002@kiot.ac.in | D3: Finished | E3: 12 August 2026 9:31 PM | F3: 12 August 2026 9:36 PM | G3: 5 mins 19 secs | H3: 22.50 | I3: 13.50 | J3: 9.00
A4: S | B4: ABINESH | C4: 2k24aids003@kiot.ac.in | D4: Finished | E4: 12 August 2026 6:57 PM | F4: 12 August 2026 7:18 PM | G4: 21 mins | H4: 22.00 | I4: 12.00 | J4: 10.00
A5: D | B5: ABISHEK | C5: 2k24aids004@kiot.ac.in | D5: Finished | E5: 12 August 2026 2:09 PM | F5: 12 August 2026 2:11 PM | G5: 1 min 27 secs | H5: 25.00 | I5: 15.00 | J5: 10.00
A6: A | B6: AJAY DEV | C6: 2k24aids005@kiot.ac.in | D6: Finished | E6: 12 August 2026 8:10 PM | F6: 12 August 2026 8:23 PM | G6: 13 mins 2 secs | H6: 23.50 | I6: 13.50 | J6: 10.00
A7: T | B7: AKISHASRI | C7: 2k24aids006@kiot.ac.in | D7: Finished | E7: 12 August 2026 9:34 PM | F7: 12 August 2026 9:40 PM | G7: 5 mins 26 secs | H7: 25.00 | I7: 15.00 | J7: 10.00
A8: P | B8: ARCHANA | C8: 2k24aids007@kiot.ac.in | D8: Finished | E8: 16 August 2026 8:38 PM | F8: 16 August 2026 8:39 PM | G8: 1 min 40 secs | H8: 25.00 | I8: 15.00 | J8: 10.00
A9: V | B9: ASHIKA | C9: 2k24aids008@kiot.ac.in | D9: Finished | E9: 12 August 2026 2:49 PM | F9: 12 August 2026 2:57 PM | G9: 7 mins 16 secs | H9: 23.50 | I9: 13.50 | J9: 10.00
A10: M | B10: BAKKIYALAKSHMI | C10: 2k24aids009@kiot.ac.in | D10: Finished | E10: 13 August 2026 8:30 PM | F10: 13 August 2026 9:00 PM | G10: 30 mins | H10: 25.00 | I10: 15.00 | J10: 10.00
A11: V | B11: BALAJI | C11: 2k24aids010@kiot.ac.in | D11: Finished | E11: 12 August 2026 2:06 PM | F11: 12 August 2026 2:36 PM | G11: 30 mins | H11: 0.00 | I11: 0.00 | J11: 0.00
A12: V | B12: BALAJI | C12: 2k24aids010@kiot.ac.in | D12: Finished | E12: 13 August 2026 6:36 AM | F12: 13 August 2026 6:49 AM | G12: 12 mins 59 secs | H12: 21.50 | I12: 13.50 | J12: 8.00
... A629: J | B629: Vignesh | C629: 2k24me131@kiot.ac.in | D629: In progress | E629: 12 August 2026 11:37 AM | F629: - | G629: - | H629: - | I629: 10.50 | J629: -
A630: Overall average | H630: 21.85 | I630: 12.92 | J630: 8.93

Sheet Department % Report
B1: KNOWLEDGE INSTITUTE OF TECHNOLOGY, SALEM
B2: Centre for Career Development and Training (CDT)
B3: Coding Skills - I (2028 Batch)
B4: Continuous Assessment - Performance Analysis as on date (25.08.2026)
B5: Department | C5: Good >=75% | D5: Satisfactory 50-74.99% | E5: Need Attention 25-49.99% | F5: Intervention <25% | G5: Not Completed | H5: Not Started | I5: Grand Total
B6: AI&DS | C6: =COUNTIFS('Overall Analysis'!$A:$A,$B6,'Overall Analysis'!$H:$H,">=75") -> 122 | D6: =COUNTIFS('Overall Analysis'!$A:$A,$B6,'Overall Analysis'!$H:$H,">=50", 'Overall Analysis'!$H:$H,"<=74.99") -> 5 | E6: =COUNTIFS('Overall Analysis'!$A:$A,$B6,'Overall Analysis'!$H:$H,">=25", 'Overall Analysis'!$H:$H,"<=49.99") -> 1 | F6: =COUNTIFS('Overall Analysis'!$A:$A,$B6,'Overall Analysis'!$H:$H,"<24.99") -> 0 | G6: =COUNTIFS('Overall Analysis'!$A:$A,$B6,'Overall Analysis'!$J:$J,"NotCompleted") -> 1 | H6: =COUNTIFS('Overall Analysis'!$A:$A,$B6,'Overall Analysis'!$J:$J,"Not Attempted") -> 0 | I6: =COUNTIF('Overall Analysis'!$A:$A,$B6) -> 129
B7: CIVIL | C7: =COUNTIFS('Overall Analysis'!$A:$A,$B7,'Overall Analysis'!$H:$H,">=75") -> 0 | D7: =COUNTIFS('Overall Analysis'!$A:$A,$B7,'Overall Analysis'!$H:$H,">=50", 'Overall Analysis'!$H:$H,"<=74.99") -> 0 | E7: =COUNTIFS('Overall Analysis'!$A:$A,$B7,'Overall Analysis'!$H:$H,">=25", 'Overall Analysis'!$H:$H,"<=49.99") -> 0 | F7: =COUNTIFS('Overall Analysis'!$A:$A,$B7,'Overall Analysis'!$H:$H,"<24.99") -> 0 | G7: =COUNTIFS('Overall Analysis'!$A:$A,$B7,'Overall Analysis'!$J:$J,"NotCompleted") -> 12 | H7: =COUNTIFS('Overall Analysis'!$A:$A,$B7,'Overall Analysis'!$J:$J,"Not Attempted") -> 21 | I7: =COUNTIF('Overall Analysis'!$A:$A,$B7) -> 33
B8: CSBS | C8: =COUNTIFS('Overall Analysis'!$A:$A,$B8,'Overall Analysis'!$H:$H,">=75") -> 33 | D8: =COUNTIFS('Overall Analysis'!$A:$A,$B8,'Overall Analysis'!$H:$H,">=50", 'Overall Analysis'!$H:$H,"<=74.99") -> 13 | E8: =COUNTIFS('Overall Analysis'!$A:$A,$B8,'Overall Analysis'!$H:$H,">=25", 'Overall Analysis'!$H:$H,"<=49.99") -> 2 | F8: =COUNTIFS('Overall Analysis'!$A:$A,$B8,'Overall Analysis'!$H:$H,"<24.99") -> 0 | G8: =COUNTIFS('Overall Analysis'!$A:$A,$B8,'Overall Analysis'!$J:$J,"NotCompleted") -> 13 | H8: =COUNTIFS('Overall Analysis'!$A:$A,$B8,'Overall Analysis'!$J:$J,"Not Attempted") -> 1 | I8: =COUNTIF('Overall Analysis'!$A:$A,$B8) -> 62
B9: CSE | C9: =COUNTIFS('Overall Analysis'!$A:$A,$B9,'Overall Analysis'!$H:$H,">=75") -> 87 | D9: =COUNTIFS('Overall Analysis'!$A:$A,$B9,'Overall Analysis'!$H:$H,">=50", 'Overall Analysis'!$H:$H,"<=74.99") -> 8 | E9: =COUNTIFS('Overall Analysis'!$A:$A,$B9,'Overall Analysis'!$H:$H,">=25", 'Overall Analysis'!$H:$H,"<=49.99") -> 2 | F9: =COUNTIFS('Overall Analysis'!$A:$A,$B9,'Overall Analysis'!$H:$H,"<24.99") -> 1 | G9: =COUNTIFS('Overall Analysis'!$A:$A,$B9,'Overall Analysis'!$J:$J,"NotCompleted") -> 102 | H9: =COUNTIFS('Overall Analysis'!$A:$A,$B9,'Overall Analysis'!$J:$J,"Not Attempted") -> 64 | I9: =COUNTIF('Overall Analysis'!$A:$A,$B9) -> 264
B10: ECE | C10: =COUNTIFS('Overall Analysis'!$A:$A,$B10,'Overall Analysis'!$H:$H,">=75") -> 125 | D10: =COUNTIFS('Overall Analysis'!$A:$A,$B10,'Overall Analysis'!$H:$H,">=50", 'Overall Analysis'!$H:$H,"<=74.99") -> 10 | E10: =COUNTIFS('Overall Analysis'!$A:$A,$B10,'Overall Analysis'!$H:$H,">=25", 'Overall Analysis'!$H:$H,"<=49.99") -> 6 | F10: =COUNTIFS('Overall Analysis'!$A:$A,$B10,'Overall Analysis'!$H:$H,"<24.99") -> 0 | G10: =COUNTIFS('Overall Analysis'!$A:$A,$B10,'Overall Analysis'!$J:$J,"NotCompleted") -> 45 | H10: =COUNTIFS('Overall Analysis'!$A:$A,$B10,'Overall Analysis'!$J:$J,"Not Attempted") -> 11 | I10: =COUNTIF('Overall Analysis'!$A:$A,$B10) -> 197
B11: EEE | C11: =COUNTIFS('Overall Analysis'!$A:$A,$B11,'Overall Analysis'!$H:$H,">=75") -> 9 | D11: =COUNTIFS('Overall Analysis'!$A:$A,$B11,'Overall Analysis'!$H:$H,">=50", 'Overall Analysis'!$H:$H,"<=74.99") -> 3 | E11: =COUNTIFS('Overall Analysis'!$A:$A,$B11,'Overall Analysis'!$H:$H,">=25", 'Overall Analysis'!$H:$H,"<=49.99") -> 1 | F11: =COUNTIFS('Overall Analysis'!$A:$A,$B11,'Overall Analysis'!$H:$H,"<24.99") -> 0 | G11: =COUNTIFS('Overall Analysis'!$A:$A,$B11,'Overall Analysis'!$J:$J,"NotCompleted") -> 29 | H11: =COUNTIFS('Overall Analysis'!$A:$A,$B11,'Overall Analysis'!$J:$J,"Not Attempted") -> 23 | I11: =COUNTIF('Overall Analysis'!$A:$A,$B11) -> 65
B12: IT | C12: =COUNTIFS('Overall Analysis'!$A:$A,$B12,'Overall Analysis'!$H:$H,">=75") -> 47 | D12: =COUNTIFS('Overall Analysis'!$A:$A,$B12,'Overall Analysis'!$H:$H,">=50", 'Overall Analysis'!$H:$H,"<=74.99") -> 6 | E12: =COUNTIFS('Overall Analysis'!$A:$A,$B12,'Overall Analysis'!$H:$H,">=25", 'Overall Analysis'!$H:$H,"<=49.99") -> 0 | F12: =COUNTIFS('Overall Analysis'!$A:$A,$B12,'Overall Analysis'!$H:$H,"<24.99") -> 0 | G12: =COUNTIFS('Overall Analysis'!$A:$A,$B12,'Overall Analysis'!$J:$J,"NotCompleted") -> 71 | H12: =COUNTIFS('Overall Analysis'!$A:$A,$B12,'Overall Analysis'!$J:$J,"Not Attempted") -> 4 | I12: =COUNTIF('Overall Analysis'!$A:$A,$B12) -> 128
B13: Mech. | C13: =COUNTIFS('Overall Analysis'!$A:$A,$B13,'Overall Analysis'!$H:$H,">=75") -> 8 | D13: =COUNTIFS('Overall Analysis'!$A:$A,$B13,'Overall Analysis'!$H:$H,">=50", 'Overall Analysis'!$H:$H,"<=74.99") -> 3 | E13: =COUNTIFS('Overall Analysis'!$A:$A,$B13,'Overall Analysis'!$H:$H,">=25", 'Overall Analysis'!$H:$H,"<=49.99") -> 0 | F13: =COUNTIFS('Overall Analysis'!$A:$A,$B13,'Overall Analysis'!$H:$H,"<24.99") -> 1 | G13: =COUNTIFS('Overall Analysis'!$A:$A,$B13,'Overall Analysis'!$J:$J,"NotCompleted") -> 37 | H13: =COUNTIFS('Overall Analysis'!$A:$A,$B13,'Overall Analysis'!$J:$J,"Not Attempted") -> 85 | I13: =COUNTIF('Overall Analysis'!$A:$A,$B13) -> 134
B14: Percentage | C14: =C15/I15*100 -> 42.588933 | D14: =D15/I15*100 -> 4.743083 | E14: =E15/I15*100 -> 1.1857708 | F14: =F15/I15*100 -> 0.19762846 | G14: =G15/I15*100 -> 30.632411 | H14: =H15/I15*100 -> 20.652174
B15: Grand Total | C15: =SUM(C6:C13) -> 431 | D15: =SUM(D6:D13) -> 48 | E15: =SUM(E6:E13) -> 12 | F15: =SUM(F6:F13) -> 2 | G15: =SUM(G6:G13) -> 310 | H15: =SUM(H6:H13) -> 209 | I15: =SUM(I6:I13) -> 1012
